Workbook

Sheet Resumen Monte Carlo
A1: FINCA LAS MARGARITAS - Simulación actualizada con Cuadro 1 del artículo
A2: Generado: 24/05/2026 | Vacas adultas: 68 | Novillas reemplazo: 14 (20% con TDIv+TMv no modificados)
A4: Bloque | B4: Código | C4: Variable | D4: Base usada | E4: Dispersión usada | F4: Media simulada | G4: Dispersión simulada | H4: n | I4: Fuente / comentario
A5: Crecimiento | B5: Ag | C5: a (Gompertz) | D5: 487.4 | E5: 10 | F5: 487.39971 | G5: 10.000283 | H5: 68 | I5: Base imagen; dispersión Cuadro 1
A6: Crecimiento | B6: Bg | C6: b (Gompertz) | D6: 1.1 | E6: 0.05 | F6: 1.0999706 | G6: 0.049991931 | H6: 68 | I6: Base imagen; dispersión Cuadro 1
A7: Crecimiento | B7: Cg | C7: c (Gompertz) | D7: 0.1101 | E7: 0.005 | F7: 0.11010147 | G7: 0.0050027602 | H7: 68 | I7: Base imagen; dispersión Cuadro 1; t en meses para edad de servicio
A8: Crecimiento | B8: PIA | C8: Peso a 1er servicio | D8: 270 | E8: 10 | F8: 270 | G8: 9.9641332 | H8: 82 | I8: Base imagen; dispersión Cuadro 1
A9: Hato | B9: VA | C9: Vacas adultas | D9: 68 | F9: 68 | H9: 1 | I9: Constante de la imagen
A10: Producción | B10: a | C10: a (Wood) | D10: 18.85 | E10: 4.5 | F10: 18.850059 | G10: 4.5000423 | H10: 68 | I10: Base imagen; dispersión Cuadro 1
A11: Producción | B11: b | C11: b (Wood) | D11: 0.62 | E11: 0.00504 | F11: 0.62000015 | G11: 0.0050402847 | H11: 68 | I11: Base imagen; dispersión Cuadro 1
A12: Producción | B12: c | C12: c (Wood) | D12: 0.132 | E12: 0.00077 | F12: 0.13199971 | G12: 0.00076941531 | H12: 68 | I12: Base imagen; dispersión Cuadro 1
A13: Producción | B13: DLAC | C13: Longitud de lactancia | D13: 305 | E13: 40 | F13: 305 | G13: 40.018652 | H13: 68 | I13: Base imagen; dispersión Cuadro 1; truncada a rango plausible
A14: Composición | B14: %GR | C14: Grasa en leche | D14: 4.32 | E14: 0.65 | F14: 4.3202941 | G14: 0.6497852 | H14: 68 | I14: Base imagen; dispersión Cuadro 1
A15: Composición | B15: %PR | C15: Proteína en leche | D15: 3.5 | E15: 0.28 | F15: 3.5004412 | G15: 0.28004495 | H15: 68 | I15: Base imagen; dispersión Cuadro 1
A16: Composición | B16: %LM | C16: Lactosa + minerales en leche | D16: 5.45 | F16: 5.45 | G16: 0 | H16: 68 | I16: Base imagen; constante
A17: Reemplazo | B17: TDIv+TMv | C17: Tasa esperada de reemplazo adulta | D17: 20 | F17: 20.588235 | H17: 14 | I17: Parámetros no solicitados se mantuvieron: TDIv + TMv
A18: Reproducción novillas | B18: IAC | C18: Intervalo 1er servicio-concepción | D18: 21 | E18: Discreta | F18: 21 | G18: 20.176147 | H18: 14 | I18: Soporte discreto Cuadro 1: 0, 21, 42, 63 días
A19: Salud | B19: IMC | C19: Incidencia mastitis clínica | D19: 12 | E19: 2 | F19: 11.764706 | H19: 8 | I19: No solicitado; conservado de la planilla anterior
A22: Parámetros modificados según solicitud
A23: Nota | B23: Se cambiaron únicamente los parámetros listados por el usuario: Gompertz a/b/c, PIA, VA, Wood a/b/c, DLAC, % grasa, % proteína y % lactosa+minerales.
A24: Nota | B24: Los valores base provienen de la imagen adjunta; las dispersiones usadas para esos parámetros provienen del Cuadro 1 del artículo adjunto.
A25: Nota | B25: El número de novillas se recalculó con la tasa de reemplazo que ya tenía la planilla anterior porque TDIv y TMv no fueron parte de los parámetros solicitados para cambio.
A26: Nota | B26: Todos los animales se mantienen como H+J- y las novillas se conservan como preñadas.

Sheet 1. Demografía
A1: ID Animal | B1: Nombre | C1: Raza | D1: Categoría | E1: Fecha nacimiento | F1: Edad (meses) | G1: Edad al registro | H1: Núm. Parto | I1: Peso vivo (kg) | J1: a (Gompertz) | K1: b (Gompertz) | L1: k (Gompertz) | M1: c (Gompertz) | N1: Edad 1er servicio (mes) | O1: Peso 1er servicio (kg) | P1: Intervalo 1er serv.-concep. novillas (d) | Q1: Edad 1er parto (mes) | R1: Estado | S1: Fecha de salida | T1: Motivo salida / Observación
A2: 1 | B2: Sally | C2: H+J- | D2: Vaca lactante | E2: 45311 | F2: =IFERROR(IF(E2="","",(TODAY()-E2)/30.4),"") -> 28.157895 | G2: 28.125 | H2: 1 | I2: 458 | J2: 476.66 | K2: 1.104 | L2: 0.1146 | M2: =L2/30.4 -> 0.0037697368 | N2: 14.8 | O2: 274 | Q2: 24 | R2: Activa
A3: 2 | B3: Berta | C3: H+J- | D3: Vaca lactante | E3: 45327 | F3: =IFERROR(IF(E3="","",(TODAY()-E3)/30.4),"") -> 27.631579 | G3: 27.598684 | H3: 1 | I3: 479 | J3: 497.32 | K3: 1.091 | L3: 0.1143 | M3: =L3/30.4 -> 0.0037598684 | N3: 14.4 | O3: 281 | Q3: 25 | R3: Activa
A4: 3 | B4: Mona | C4: H+J- | D4: Vaca lactante | E4: 45315 | F4: =IFERROR(IF(E4="","",(TODAY()-E4)/30.4),"") -> 28.026316 | G4: 27.993421 | H4: 1 | I4: 467 | J4: 486.67 | K4: 1.006 | L4: 0.1163 | M4: =L4/30.4 -> 0.0038256579 | N4: 13.4 | O4: 273 | Q4: 22.8 | R4: Activa
A5: 4 | B5: Luna | C5: H+J- | D5: Vaca lactante | E5: 45299 | F5: =IFERROR(IF(E5="","",(TODAY()-E5)/30.4),"") -> 28.552632 | G5: 28.519737 | H5: 1 | I5: 463 | J5: 480.42 | K5: 1.129 | L5: 0.114 | M5: =L5/30.4 -> 0.00375 | N5: 14.7 | O5: 269 | Q5: 26.2 | R5: Activa
A6: 5 | B6: Luci | C6: H+J- | D6: Vaca lactante | E6: 45182 | F6: =IFERROR(IF(E6="","",(TODAY()-E6)/30.4),"") -> 32.401316 | G6: 32.368421 | H6: 1 | I6: 484 | J6: 502.22 | K6: 1.097 | L6: 0.1085 | M6: =L6/30.4 -> 0.0035690789 | N6: 14.8 | O6: 275 | Q6: 25.4 | R6: Activa
A7: 6 | B7: Mariposa | C7: H+J- | D7: Vaca lactante | E7: 45216 | F7: =IFERROR(IF(E7="","",(TODAY()-E7)/30.4),"") -> 31.282895 | G7: 31.25 | H7: 1 | I7: 475 | J7: 490.96 | K7: 1.096 | L7: 0.1098 | M7: =L7/30.4 -> 0.0036118421 | N7: 15.1 | O7: 277 | Q7: 25 | R7: Activa
A8: 7 | B8: Rola | C8: H+J- | D8: Vaca lactante | E8: 45189 | F8: =IFERROR(IF(E8="","",(TODAY()-E8)/30.4),"") -> 32.171053 | G8: 32.138158 | H8: 1 | I8: 466 | J8: 487.66 | K8: 1.077 | L8: 0.1059 | M8: =L8/30.4 -> 0.0034835526 | N8: 15.2 | O8: 271 | Q8: 25.1 | R8: Activa
A9: 8 | B9: Prisma | C9: H+J- | D9: Vaca lactante | E9: 45351 | F9: =IFERROR(IF(E9="","",(TODAY()-E9)/30.4),"") -> 26.842105 | G9: 26.809211 | H9: 1 | I9: 454 | J9: 480.02 | K9: 1.093 | L9: 0.111 | M9: =L9/30.4 -> 0.0036513158 | N9: 15.5 | O9: 282 | Q9: 25.4 | R9: Activa
A10: 9 | B10: Margarita | C10: H+J- | D10: Vaca lactante | E10: 45100 | F10: =IFERROR(IF(E10="","",(TODAY()-E10)/30.4),"") -> 35.098684 | G10: 35.065789 | H10: 1 | I10: 450 | J10: 465.98 | K10: 1.158 | L10: 0.1068 | M10: =L10/30.4 -> 0.0035131579 | N10: 17.4 | O10: 283 | Q10: 26.6 | R10: Activa
A11: 10 | B11: Lola | C11: H+J- | D11: Vaca lactante | E11: 45191 | F11: =IFERROR(IF(E11="","",(TODAY()-E11)/30.4),"") -> 32.105263 | G11: 32.072368 | H11: 1 | I11: 467 | J11: 486.79 | K11: 1.091 | L11: 0.1088 | M11: =L11/30.4 -> 0.0035789474 | N11: 15.2 | O11: 275 | Q11: 25.9 | R11: Activa
A12: 11 | B12: Paca | C12: H+J- | D12: Vaca lactante | E12: 45276 | F12: =IFERROR(IF(E12="","",(TODAY()-E12)/30.4),"") -> 29.309211 | G12: 29.276316 | H12: 1 | I12: 467 | J12: 487.23 | K12: 1.099 | L12: 0.1151 | M12: =L12/30.4 -> 0.0037861842 | N12: 14.7 | O12: 280 | Q12: 24 | R12: Activa
A13: 12 | B13: Mucca | C13: H+J- | D13: Vaca lactante | E13: 45297 | F13: =IFERROR(IF(E13="","",(TODAY()-E13)/30.4),"") -> 28.618421 | G13: 28.585526 | H13: 1 | I13: 464 | J13: 484.23 | K13: 1.008 | L13: 0.1072 | M13: =L13/30.4 -> 0.0035263158 | N13: 14.8 | O13: 277 | Q13: 23.9 | R13: Activa
... A69: 68 | B69: Celeste | C69: H+J- | D69: Vaca lactante | E69: 45256 | F69: =IFERROR(IF(E69="","",(TODAY()-E69)/30.4),"") -> 29.967105 | G69: 29.934211 | H69: 1 | I69: 484 | J69: 507.13 | K69: 1.209 | L69: 0.1126 | M69: =L69/30.4 -> 0.0037039474 | N69: 14.9 | O69: 271 | Q69: 24.2 | R69: Activa
A71: 69 | B71: Dafne | C71: H+J- | D71: Novilla preñada | E71: 45582 | F71: =IFERROR(IF(E71="","",(TODAY()-E71)/30.4),"") -> 19.243421 | G71: 19.210526 | H71: 0 | I71: 438 | J71: 498.3 | K71: 1.008 | L71: 0.1077 | M71: =L71/30.4 -> 0.0035427632 | N71: 14.3 | O71: 277 | P71: 21 | Q71: 24.4 | R71: Activa
A72: 70 | B72: Elisa | C72: H+J- | D72: Novilla preñada | E72: 45567 | F72: =IFERROR(IF(E72="","",(TODAY()-E72)/30.4),"") -> 19.736842 | G72: 19.703947 | H72: 0 | I72: 423 | J72: 488.77 | K72: 1.148 | L72: 0.1021 | M72: =L72/30.4 -> 0.0033585526 | N72: 16.2 | O72: 268 | P72: 0 | Q72: 25.5 | R72: Activa
A73: 71 | B73: Fiona | C73: H+J- | D73: Novilla preñada | E73: 45598 | F73: =IFERROR(IF(E73="","",(TODAY()-E73)/30.4),"") -> 18.717105 | G73: 18.684211 | H73: 0 | I73: 419 | J73: 475.16 | K73: 1.107 | L73: 0.1173 | M73: =L73/30.4 -> 0.0038585526 | N73: 14.6 | O73: 276 | P73: 42 | Q73: 25.2 | R73: Activa
A74: 72 | B74: Greta | C74: H+J- | D74: Novilla preñada | E74: 45494 | F74: =IFERROR(IF(E74="","",(TODAY()-E74)/30.4),"") -> 22.138158 | G74: 22.105263 | H74: 0 | I74: 451 | J74: 495.61 | K74: 1.113 | L74: 0.1164 | M74: =L74/30.4 -> 0.0038289474 | N74: 14.2 | O74: 277 | P74: 0 | Q74: 23.4 | R74: Activa
A75: 73 | B75: Helena | C75: H+J- | D75: Novilla preñada | E75: 45497 | F75: =IFERROR(IF(E75="","",(TODAY()-E75)/30.4),"") -> 22.039474 | G75: 22.006579 | H75: 0 | I75: 439 | J75: 486.58 | K75: 1.097 | L75: 0.1046 | M75: =L75/30.4 -> 0.0034407895 | N75: 15.2 | O75: 264 | P75: 21 | Q75: 25.1 | R75: Activa
A76: 74 | B76: Iris | C76: H+J- | D76: Novilla preñada | E76: 45509 | F76: =IFERROR(IF(E76="","",(TODAY()-E76)/30.4),"") -> 21.644737 | G76: 21.611842 | H76: 0 | I76: 454 | J76: 505.25 | K76: 1.093 | L76: 0.1076 | M76: =L76/30.4 -> 0.0035394737 | N76: 15.6 | O76: 290 | P76: 42 | Q76: 26.2 | R76: Activa
A77: 75 | B77: Jacinta | C77: H+J- | D77: Novilla preñada | E77: 45500 | F77: =IFERROR(IF(E77="","",(TODAY()-E77)/30.4),"") -> 21.940789 | G77: 21.907895 | H77: 0 | I77: 437 | J77: 488.63 | K77: 1.161 | L77: 0.1106 | M77: =L77/30.4 -> 0.0036381579 | N77: 15.3 | O77: 271 | P77: 21 | Q77: 25.2 | R77: Activa
A78: 76 | B78: Kora | C78: H+J- | D78: Novilla preñada | E78: 45640 | F78: =IFERROR(IF(E78="","",(TODAY()-E78)/30.4),"") -> 17.335526 | G78: 17.302632 | H78: 0 | I78: 413 | J78: 484.51 | K78: 1.114 | L78: 0.1111 | M78: =L78/30.4 -> 0.0036546053 | N78: 14.9 | O78: 271 | P78: 0 | Q78: 24.2 | R78: Activa
A79: 77 | B79: Lía | C79: H+J- | D79: Novilla preñada | E79: 45552 | F79: =IFERROR(IF(E79="","",(TODAY()-E79)/30.4),"") -> 20.230263 | G79: 20.197368 | H79: 0 | I79: 439 | J79: 485.14 | K79: 1.057 | L79: 0.1173 | M79: =L79/30.4 -> 0.0038585526 | N79: 13.5 | O79: 269 | P79: 63 | Q79: 25 | R79: Activa
A80: 78 | B80: Maia | C80: H+J- | D80: Novilla preñada | E80: 45470 | F80: =IFERROR(IF(E80="","",(TODAY()-E80)/30.4),"") -> 22.927632 | G80: 22.894737 | H80: 0 | I80: 445 | J80: 482.37 | K80: 1.201 | L80: 0.1153 | M80: =L80/30.4 -> 0.0037927632 | N80: 14.4 | O80: 256 | P80: 21 | Q80: 24.2 | R80: Activa
A81: 79 | B81: Noa | C81: H+J- | D81: Novilla preñada | E81: 45497 | F81: =IFERROR(IF(E81="","",(TODAY()-E81)/30.4),"") -> 22.039474 | G81: 22.006579 | H81: 0 | I81: 447 | J81: 494.01 | K81: 1.113 | L81: 0.1071 | M81: =L81/30.4 -> 0.0035230263 | N81: 14.7 | O81: 263 | P81: 0 | Q81: 24 | R81: Activa
A82: 80 | B82: Orión | C82: H+J- | D82: Novilla preñada | E82: 45500 | F82: =IFERROR(IF(E82="","",(TODAY()-E82)/30.4),"") -> 21.940789 | G82: 21.907895 | H82: 0 | I82: 443 | J82: 489.72 | K82: 1.073 | L82: 0.106 | M82: =L82/30.4 -> 0.0034868421 | N82: 15.8 | O82: 283 | P82: 21 | Q82: 25.9 | R82: Activa
... A84: 82 | B84: Quilla | C84: H+J- | D84: Novilla preñada | E84: 45582 | F84: =IFERROR(IF(E84="","",(TODAY()-E84)/30.4),"") -> 19.243421 | G84: 19.210526 | H84: 0 | I84: 430 | J84: 485.61 | K84: 1.081 | L84: 0.1122 | M84: =L84/30.4 -> 0.0036907895 | N84: 13.7 | O84: 258 | P84: 0 | Q84: 22.9 | R84: Activa

Sheet 2. Producción
A1: ID Animal | B1: Núm. Lactancia | C1: Fecha parto | D1: Fecha secado | E1: Longitud lactancia (d) | F1: Producción total (kg) | G1: Producción al pico (kg/d) | H1: Día del pico | I1: a (Wood) | J1: b (Wood) | K1: k semanal (Wood) | L1: c (Wood) | M1: % Grasa | N1: % Proteína | O1: % Lactosa+minerales | P1: Observaciones
A2: 1 | B2: 1 | C2: 46041 | D2: 46328 | E2: =IFERROR(IF(OR(C2="",D2=""),"",D2-C2),"") -> 287 | F2: {=SUM(I2*(_xlfn.SEQUENCE(E2)^J2)*EXP(-L2*_xlfn.SEQUENCE(E2)))} -> 5130.7641 | G2: =I2*((J2/L2)^J2)*EXP(-J2) -> 25.050265 | H2: =J2/L2 -> 28.208801 | I2: 18.204 | J2: 0.13645 | K2: 0.03386 | L2: =K2/7 -> 0.0048371429 | M2: 4.73 | N2: 3.85 | O2: 5.45
A3: 2 | B3: 1 | C3: 46087 | D3: 46415 | E3: =IFERROR(IF(OR(C3="",D3=""),"",D3-C3),"") -> 328 | F3: {=SUM(I3*(_xlfn.SEQUENCE(E3)^J3)*EXP(-L3*_xlfn.SEQUENCE(E3)))} -> 5672.929 | G3: =I3*((J3/L3)^J3)*EXP(-J3) -> 27.030624 | H3: =J3/L3 -> 24.461988 | I3: 20.517 | J3: 0.12549 | K3: 0.03591 | L3: =K3/7 -> 0.00513 | M3: 4.36 | N3: 3.53 | O3: 5.45
A4: 3 | B4: 1 | C4: 46008 | D4: 46376 | E4: =IFERROR(IF(OR(C4="",D4=""),"",D4-C4),"") -> 368 | F4: {=SUM(I4*(_xlfn.SEQUENCE(E4)^J4)*EXP(-L4*_xlfn.SEQUENCE(E4)))} -> 7148.413 | G4: =I4*((J4/L4)^J4)*EXP(-J4) -> 31.079328 | H4: =J4/L4 -> 27.170998 | I4: 22.965 | J4: 0.13143 | K4: 0.03386 | L4: =K4/7 -> 0.0048371429 | M4: 4.81 | N4: 3.34 | O4: 5.45
A5: 4 | B5: 1 | C5: 46095 | D5: 46383 | E5: =IFERROR(IF(OR(C5="",D5=""),"",D5-C5),"") -> 288 | F5: {=SUM(I5*(_xlfn.SEQUENCE(E5)^J5)*EXP(-L5*_xlfn.SEQUENCE(E5)))} -> 6097.1193 | G5: =I5*((J5/L5)^J5)*EXP(-J5) -> 30.389319 | H5: =J5/L5 -> 25.690825 | I5: 22.816 | J5: 0.12761 | K5: 0.03477 | L5: =K5/7 -> 0.0049671429 | M5: 4.73 | N5: 3.53 | O5: 5.45
A6: 5 | B6: 1 | C6: 45954 | D6: 46233 | E6: =IFERROR(IF(OR(C6="",D6=""),"",D6-C6),"") -> 279 | F6: {=SUM(I6*(_xlfn.SEQUENCE(E6)^J6)*EXP(-L6*_xlfn.SEQUENCE(E6)))} -> 5972.6334 | G6: =I6*((J6/L6)^J6)*EXP(-J6) -> 29.526832 | H6: =J6/L6 -> 27.636583 | I6: 21.801 | J6: 0.1308 | K6: 0.03313 | L6: =K6/7 -> 0.0047328571 | M6: 4.31 | N6: 3.7 | O6: 5.45
A7: 6 | B7: 1 | C7: 45976 | D7: 46228 | E7: =IFERROR(IF(OR(C7="",D7=""),"",D7-C7),"") -> 252 | F7: {=SUM(I7*(_xlfn.SEQUENCE(E7)^J7)*EXP(-L7*_xlfn.SEQUENCE(E7)))} -> 3842.6997 | G7: =I7*((J7/L7)^J7)*EXP(-J7) -> 20.441349 | H7: =J7/L7 -> 27.844178 | I7: 14.78 | J7: 0.13938 | K7: 0.03504 | L7: =K7/7 -> 0.0050057143 | M7: 3.82 | N7: 3.81 | O7: 5.45
A8: 7 | B8: 1 | C8: 45952 | D8: 46281 | E8: =IFERROR(IF(OR(C8="",D8=""),"",D8-C8),"") -> 329 | F8: {=SUM(I8*(_xlfn.SEQUENCE(E8)^J8)*EXP(-L8*_xlfn.SEQUENCE(E8)))} -> 4501.1503 | G8: =I8*((J8/L8)^J8)*EXP(-J8) -> 20.539837 | H8: =J8/L8 -> 27.214583 | I8: 15.202 | J8: 0.13063 | K8: 0.0336 | L8: =K8/7 -> 0.0048 | M8: 5.48 | N8: 3.72 | O8: 5.45
A9: 8 | B9: 1 | C9: 46123 | D9: 46429 | E9: =IFERROR(IF(OR(C9="",D9=""),"",D9-C9),"") -> 306 | F9: {=SUM(I9*(_xlfn.SEQUENCE(E9)^J9)*EXP(-L9*_xlfn.SEQUENCE(E9)))} -> 5104.2001 | G9: =I9*((J9/L9)^J9)*EXP(-J9) -> 23.903377 | H9: =J9/L9 -> 28.756587 | I9: 17.294 | J9: 0.13721 | K9: 0.0334 | L9: =K9/7 -> 0.0047714286 | M9: 3.82 | N9: 3.27 | O9: 5.45
A10: 9 | B10: 1 | C10: 45909 | D10: 46165 | E10: =IFERROR(IF(OR(C10="",D10=""),"",D10-C10),"") -> 256 | F10: {=SUM(I10*(_xlfn.SEQUENCE(E10)^J10)*EXP(-L10*_xlfn.SEQUENCE(E10)))} -> 4486.7575 | G10: =I10*((J10/L10)^J10)*EXP(-J10) -> 23.897244 | H10: =J10/L10 -> 25.536515 | I10: 17.985 | J10: 0.12688 | K10: 0.03478 | L10: =K10/7 -> 0.0049685714 | M10: 2.8 | N10: 3.79 | O10: 5.45
A11: 10 | B11: 1 | C11: 45978 | D11: 46325 | E11: =IFERROR(IF(OR(C11="",D11=""),"",D11-C11),"") -> 347 | F11: {=SUM(I11*(_xlfn.SEQUENCE(E11)^J11)*EXP(-L11*_xlfn.SEQUENCE(E11)))} -> 5938.8449 | G11: =I11*((J11/L11)^J11)*EXP(-J11) -> 26.002223 | H11: =J11/L11 -> 29.19723 | I11: 18.715 | J11: 0.13852 | K11: 0.03321 | L11: =K11/7 -> 0.0047442857 | M11: 4.53 | N11: 3.44 | O11: 5.45
A12: 11 | B12: 1 | C12: 46006 | D12: 46298 | E12: =IFERROR(IF(OR(C12="",D12=""),"",D12-C12),"") -> 292 | F12: {=SUM(I12*(_xlfn.SEQUENCE(E12)^J12)*EXP(-L12*_xlfn.SEQUENCE(E12)))} -> 2619.5987 | G12: =I12*((J12/L12)^J12)*EXP(-J12) -> 13.009821 | H12: =J12/L12 -> 26.273136 | I12: 9.612 | J12: 0.13343 | K12: 0.03555 | L12: =K12/7 -> 0.0050785714 | M12: 3.94 | N12: 3.5 | O12: 5.45
A13: 12 | B13: 1 | C13: 46024 | D13: 46396 | E13: =IFERROR(IF(OR(C13="",D13=""),"",D13-C13),"") -> 372 | F13: {=SUM(I13*(_xlfn.SEQUENCE(E13)^J13)*EXP(-L13*_xlfn.SEQUENCE(E13)))} -> 4586.3721 | G13: =I13*((J13/L13)^J13)*EXP(-J13) -> 19.678377 | H13: =J13/L13 -> 28.371039 | I13: 14.275 | J13: 0.13687 | K13: 0.03377 | L13: =K13/7 -> 0.0048242857 | M13: 4.4 | N13: 3.37 | O13: 5.45
... A69: 68 | B69: 1 | C69: 45992 | D69: 46240 | E69: =IFERROR(IF(OR(C69="",D69=""),"",D69-C69),"") -> 248 | F69: {=SUM(I69*(_xlfn.SEQUENCE(E69)^J69)*EXP(-L69*_xlfn.SEQUENCE(E69)))} -> 5424.0612 | G69: =I69*((J69/L69)^J69)*EXP(-J69) -> 28.991224 | H69: =J69/L69 -> 28.01217 | I69: 21.007 | J69: 0.1381 | K69: 0.03451 | L69: =K69/7 -> 0.00493 | M69: 3.81 | N69: 3.55 | O69: 5.45

Sheet 3. Reproducción
A1: ID Animal | B1: Núm. Lactancia | C1: Fecha parto previo | D1: Fecha 1er servicio | E1: Fecha concepción | F1: Fecha siguiente parto | G1: Días abiertos (d) | H1: Intervalo 1er serv.-concep. (d) | I1: Duración preñez (d) | J1: Intervalo entre partos (d) | K1: Núm. Servicios | L1: Tipo de servicio | M1: Resultado | N1: Observaciones
A2: 1 | B2: 1 | C2: 46041 | D2: 46219 | E2: 46219 | F2: 46498 | G2: =IFERROR(IF(OR(C2="",E2=""),"",E2-C2),"") -> 178 | H2: =IFERROR(IF(OR(D2="",E2=""),"",E2-D2),"") -> 0 | I2: =IFERROR(IF(OR(E2="",F2=""),"",F2-E2),"") -> 279 | J2: =IFERROR(IF(OR(C2="",F2=""),"",F2-C2),"") -> 457 | K2: 1 | L2: IA Sexada | M2: Preñada
A3: 2 | B3: 1 | C3: 46087 | D3: 46177 | E3: 46219 | F3: 46499 | G3: =IFERROR(IF(OR(C3="",E3=""),"",E3-C3),"") -> 132 | H3: =IFERROR(IF(OR(D3="",E3=""),"",E3-D3),"") -> 42 | I3: =IFERROR(IF(OR(E3="",F3=""),"",F3-E3),"") -> 280 | J3: =IFERROR(IF(OR(C3="",F3=""),"",F3-C3),"") -> 412 | K3: 3 | L3: IA Sexada | M3: Preñada
A4: 3 | B4: 1 | C4: 46008 | D4: 46154 | E4: 46154 | F4: 46440 | G4: =IFERROR(IF(OR(C4="",E4=""),"",E4-C4),"") -> 146 | H4: =IFERROR(IF(OR(D4="",E4=""),"",E4-D4),"") -> 0 | I4: =IFERROR(IF(OR(E4="",F4=""),"",F4-E4),"") -> 286 | J4: =IFERROR(IF(OR(C4="",F4=""),"",F4-C4),"") -> 432 | K4: 1 | L4: IA Convencional | M4: Preñada
A5: 4 | B5: 1 | C5: 46095 | D5: 46168 | E5: 46231 | F5: 46517 | G5: =IFERROR(IF(OR(C5="",E5=""),"",E5-C5),"") -> 136 | H5: =IFERROR(IF(OR(D5="",E5=""),"",E5-D5),"") -> 63 | I5: =IFERROR(IF(OR(E5="",F5=""),"",F5-E5),"") -> 286 | J5: =IFERROR(IF(OR(C5="",F5=""),"",F5-C5),"") -> 422 | K5: 4 | L5: IA Convencional | M5: Preñada
A6: 5 | B6: 1 | C6: 45954 | D6: 46029 | E6: 46071 | F6: 46351 | G6: =IFERROR(IF(OR(C6="",E6=""),"",E6-C6),"") -> 117 | H6: =IFERROR(IF(OR(D6="",E6=""),"",E6-D6),"") -> 42 | I6: =IFERROR(IF(OR(E6="",F6=""),"",F6-E6),"") -> 280 | J6: =IFERROR(IF(OR(C6="",F6=""),"",F6-C6),"") -> 397 | K6: 3 | L6: IA Convencional | M6: Preñada
A7: 6 | B7: 1 | C7: 45976 | D7: 46085 | E7: 46106 | F7: 46386 | G7: =IFERROR(IF(OR(C7="",E7=""),"",E7-C7),"") -> 130 | H7: =IFERROR(IF(OR(D7="",E7=""),"",E7-D7),"") -> 21 | I7: =IFERROR(IF(OR(E7="",F7=""),"",F7-E7),"") -> 280 | J7: =IFERROR(IF(OR(C7="",F7=""),"",F7-C7),"") -> 410 | K7: 2 | L7: IA Sexada | M7: Preñada
A8: 7 | B8: 1 | C8: 45952 | D8: 46105 | E8: 46126 | F8: 46407 | G8: =IFERROR(IF(OR(C8="",E8=""),"",E8-C8),"") -> 174 | H8: =IFERROR(IF(OR(D8="",E8=""),"",E8-D8),"") -> 21 | I8: =IFERROR(IF(OR(E8="",F8=""),"",F8-E8),"") -> 281 | J8: =IFERROR(IF(OR(C8="",F8=""),"",F8-C8),"") -> 455 | K8: 2 | L8: IA Convencional | M8: Preñada
A9: 8 | B9: 1 | C9: 46123 | D9: 46232 | E9: 46253 | F9: 46532 | G9: =IFERROR(IF(OR(C9="",E9=""),"",E9-C9),"") -> 130 | H9: =IFERROR(IF(OR(D9="",E9=""),"",E9-D9),"") -> 21 | I9: =IFERROR(IF(OR(E9="",F9=""),"",F9-E9),"") -> 279 | J9: =IFERROR(IF(OR(C9="",F9=""),"",F9-C9),"") -> 409 | K9: 2 | L9: IA Convencional | M9: Preñada
A10: 9 | B10: 1 | C10: 45909 | D10: 46079 | E10: 46079 | F10: 46360 | G10: =IFERROR(IF(OR(C10="",E10=""),"",E10-C10),"") -> 170 | H10: =IFERROR(IF(OR(D10="",E10=""),"",E10-D10),"") -> 0 | I10: =IFERROR(IF(OR(E10="",F10=""),"",F10-E10),"") -> 281 | J10: =IFERROR(IF(OR(C10="",F10=""),"",F10-C10),"") -> 451 | K10: 1 | L10: IA Convencional | M10: Preñada
A11: 10 | B11: 1 | C11: 45978 | D11: 46057 | E11: 46099 | F11: 46382 | G11: =IFERROR(IF(OR(C11="",E11=""),"",E11-C11),"") -> 121 | H11: =IFERROR(IF(OR(D11="",E11=""),"",E11-D11),"") -> 42 | I11: =IFERROR(IF(OR(E11="",F11=""),"",F11-E11),"") -> 283 | J11: =IFERROR(IF(OR(C11="",F11=""),"",F11-C11),"") -> 404 | K11: 3 | L11: IA Convencional | M11: Preñada
A12: 11 | B12: 1 | C12: 46006 | D12: 46130 | E12: 46130 | F12: 46413 | G12: =IFERROR(IF(OR(C12="",E12=""),"",E12-C12),"") -> 124 | H12: =IFERROR(IF(OR(D12="",E12=""),"",E12-D12),"") -> 0 | I12: =IFERROR(IF(OR(E12="",F12=""),"",F12-E12),"") -> 283 | J12: =IFERROR(IF(OR(C12="",F12=""),"",F12-C12),"") -> 407 | K12: 1 | L12: IA Sexada | M12: Preñada
A13: 12 | B13: 1 | C13: 46024 | D13: 46156 | E13: 46156 | F13: 46434 | G13: =IFERROR(IF(OR(C13="",E13=""),"",E13-C13),"") -> 132 | H13: =IFERROR(IF(OR(D13="",E13=""),"",E13-D13),"") -> 0 | I13: =IFERROR(IF(OR(E13="",F13=""),"",F13-E13),"") -> 278 | J13: =IFERROR(IF(OR(C13="",F13=""),"",F13-C13),"") -> 410 | K13: 1 | L13: IA Convencional | M13: Preñada
... A69: 68 | B69: 1 | C69: 45992 | D69: 46134 | E69: 46134 | F69: 46416 | G69: =IFERROR(IF(OR(C69="",E69=""),"",E69-C69),"") -> 142 | H69: =IFERROR(IF(OR(D69="",E69=""),"",E69-D69),"") -> 0 | I69: =IFERROR(IF(OR(E69="",F69=""),"",F69-E69),"") -> 282 | J69: =IFERROR(IF(OR(C69="",F69=""),"",F69-C69),"") -> 424 | K69: 1 | L69: IA Convencional | M69: Preñada

Sheet 4. Salud y Mastitis
A1: ID Animal | B1: Núm. Lactancia | C1: Fecha parto | D1: Fecha evento | E1: Día de lactancia | F1: Tipo evento | G1: Severidad | H1: Días tratamiento | I1: Costo veterinario (USD) | J1: Resultado | K1: Observaciones
A2: 5 | B2: 1 | C2: 45954 | D2: 46064 | E2: =IFERROR(IF(OR(C2="",D2=""),"",D2-C2),"") -> 110 | F2: Mastitis clínica | G2: Moderada | H2: 4 | I2: 55.03 | J2: Recuperada
A3: 11 | B3: 1 | C3: 46006 | D3: 46083 | E3: =IFERROR(IF(OR(C3="",D3=""),"",D3-C3),"") -> 77 | F3: Mastitis clínica | G3: Moderada | H3: 4 | I3: 55.03 | J3: Recuperada
A4: 18 | B4: 1 | C4: 45958 | D4: 46047 | E4: =IFERROR(IF(OR(C4="",D4=""),"",D4-C4),"") -> 89 | F4: Mastitis clínica | G4: Moderada | H4: 4 | I4: 55.03 | J4: Recuperada
A5: 25 | B5: 1 | C5: 45961 | D5: 46057 | E5: =IFERROR(IF(OR(C5="",D5=""),"",D5-C5),"") -> 96 | F5: Mastitis clínica | G5: Severa | H5: 5 | I5: 55.03 | J5: Recuperada
A6: 31 | B6: 1 | C6: 46059 | D6: 46153 | E6: =IFERROR(IF(OR(C6="",D6=""),"",D6-C6),"") -> 94 | F6: Mastitis clínica | G6: Leve | H6: 3 | I6: 55.03 | J6: Recuperada
A7: 47 | B7: 1 | C7: 45944 | D7: 46057 | E7: =IFERROR(IF(OR(C7="",D7=""),"",D7-C7),"") -> 113 | F7: Mastitis clínica | G7: Severa | H7: 5 | I7: 55.03 | J7: Recuperada
A8: 53 | B8: 1 | C8: 46101 | D8: 46205 | E8: =IFERROR(IF(OR(C8="",D8=""),"",D8-C8),"") -> 104 | F8: Mastitis clínica | G8: Leve | H8: 3 | I8: 55.03 | J8: Recuperada
A9: 56 | B9: 1 | C9: 45903 | D9: 45994 | E9: =IFERROR(IF(OR(C9="",D9=""),"",D9-C9),"") -> 91 | F9: Mastitis clínica | G9: Leve | H9: 3 | I9: 55.03 | J9: Recuperada

Sheet Parámetros base
A1: Finca Las Margaritas - Parámetros Bosque húmedo premontano
A2: Parámetros de entrada del modelo
A3: Parámetros | B3: Unidades | C3: Código | D3: Distribución | E3: Base | F3: Dispersión
A4: Novillas de reemplazo:
A5: a (Gompertz) | B5: parámetro | C5: Ag | D5: Normal | E5: =AVERAGE('1. Demografía'!J71:J84) -> 487.4 | F5: =_xlfn.STDEV.P('1. Demografía'!J71:J84) -> 9.6367125
A6: b (Gompertz) | B6: parámetro | C6: Bg | D6: Normal | E6: =AVERAGE('1. Demografía'!K71:K84) -> 1.1000714 | F6: =_xlfn.STDEV.P('1. Demografía'!K71:K84) -> 0.048177446
A7: c (Gompertz) | B7: parámetro | C7: Cg | D7: Normal | E7: =AVERAGE('1. Demografía'!L71:L84) -> 0.11009286 | F7: =_xlfn.STDEV.P('1. Demografía'!L71:L84) -> 0.0048177446
A8: Peso a 1er servicio | B8: kg | C8: PIA | D8: Normal | E8: =AVERAGE('1. Demografía'!O71:O84) -> 270 | F8: =_xlfn.STDEV.P('1. Demografía'!O71:O84) -> 9.6510547
A9: Intervalo 1er serv.-concep. | B9: d | C9: IAC | D9: Discreta | E9: =AVERAGE('1. Demografía'!P71:P84) -> 21 | F9: -
A10: Desecho involuntario (reemp) | B10: % | C10: TDIr | D10: Normal | E10: 12 | F10: 2.5
A11: Desecho voluntario (reemp) | B11: % | C11: TDVr | D11: Discreta | E11: 50 | F11: -
A13: Hato en producción:
A14: Vacas adultas | B14: n | C14: VA | D14: Costante | E14: =COUNT('1. Demografía'!A2:A69) -> 68 | F14: -
A15: Desecho involuntario | B15: % | C15: TDIv | D15: Normal | E15: 18 | F15: 2
A16: Mortalidad | B16: % | C16: TMv | D16: Normal | E16: 2 | F16: 0.5
A17: Días abiertos | B17: d | C17: DA | D17: Extremo | E17: =AVERAGE('3. Reproducción'!G2:G69) -> 138 | F17: =_xlfn.STDEV.P('3. Reproducción'!G2:G69) -> 24.800972
A18: Duración de preñez | B18: d | C18: DP | D18: Normal | E18: =AVERAGE('3. Reproducción'!I2:I69) -> 282 | F18: =_xlfn.STDEV.P('3. Reproducción'!I2:I69) -> 2.995094
A19: Rendimiento en canal | B19: % | C19: RC | D19: Normal | E19: 48 | F19: 1
A20: a (Wood) | B20: parámetro | C20: a | D20: Normal | E20: =AVERAGE('2. Producción'!I2:I69) -> 18.849985 | F20: =_xlfn.STDEV.P('2. Producción'!I2:I69) -> 4.4667774
A21: b (Wood) | B21: parámetro | C21: b | D21: Normal | E21: =AVERAGE('2. Producción'!J2:J69) -> 0.13199971 | F21: =_xlfn.STDEV.P('2. Producción'!J2:J69) -> 0.0050030917
A22: c (Wood) | B22: parámetro | C22: c | D22: Normal | E22: =AVERAGE('2. Producción'!K2:K69) -> 0.034000294 | F22: =_xlfn.STDEV.P('2. Producción'!K2:K69) -> 0.00076417
A23: Longitud de lactancia | B23: d | C23: DLAC | D23: Normal | E23: =AVERAGE('2. Producción'!E2:E69) -> 305 | F23: =_xlfn.STDEV.P('2. Producción'!E2:E69) -> 39.723308
A24: Grasa en leche | B24: % | C24: %GR | D24: Normal | E24: =AVERAGE('2. Producción'!M2:M69) -> 4.3202941 | F24: =_xlfn.STDEV.P('2. Producción'!M2:M69) -> 0.64498967
A25: Proteína en leche | B25: % | C25: %PR | D25: Normal | E25: =AVERAGE('2. Producción'!N2:N69) -> 3.5004412 | F25: =_xlfn.STDEV.P('2. Producción'!N2:N69) -> 0.27797817
A26: Lactosa + minerales en leche | B26: % | C26: %LM | D26: Constante | E26: =AVERAGE('2. Producción'!O2:O69) -> 5.45 | F26: -
A27: Incidencia mastitis clínica | B27: % | C27: IMC | D27: Normal | E27: 15 | F27: 3
A28: Primer día de mastitis | B28: d | C28: DMC | D28: Exponencial | E28: =AVERAGE('4. Salud y Mastitis'!E2:E9) -> 96.75 | F28: -
A30: Parámetros económicos:
A31: Precio grasa o proteína | B31: COP kg | C31: $KGP | D31: Normal | E31: 42300 | F31: 95.44
A32: Precio lactosa + minerales | B32: COP kg | C32: $LM | D32: Normal | E32: 15000 | F32: 73
A33: Precio carne en canal | B33: COP kg | C33: $CAR | D33: Normal | E33: 20000 | F33: 73
A34: Precio novilla preñada | B34: COP | C34: $NOV | D34: Normal | E34: 3700000 | F34: 180000
A35: Costo concentrado | B35: COP kg | C35: $CON | D35: Normal | E35: 2025 | F35: 73
A36: Costo novilla preñada | B36: COP | C36: $REM | D36: Normal | E36: 2270000 | F36: 220000
A37: Costos fijos vaca adulta | B37: COP | C37: $VAC | D37: Normal | E37: 1500000 | F37: 110000
A38: Costos por administración | B38: COP | C38: $AD | D38: Costante | E38: 18000000 | F38: -

Sheet Variables salida
A1: Finca Las Margaritas - Parámetros Bosque húmedo premontano
A2: Variables de salida del modelo
A3: Parámetros | B3: Unidades | C3: Código | D3: Fórmulas de cálulo | E3: Promedio | F3: D.E.
A4: Vacas lactantes | B4: n | C4: VL | D4: VA×(1-TDIv/100)-VA×TMv/100 | E4: ='Parámetros base'!E14*(1-'Parámetros base'!E15/100)-'Parámetros base'!E14*'Parámetros base'!E16/100 -> 54.4
A5: Hembras reemplazo | B5: n | C5: HR | D5: VL×0.5× (1-TDIr/100) ×24/ EPA | E5: =E4*0.5*(1-'Parámetros base'!E10/100)*24/'Variables salida'!E13 -> 23.218424
A6: Vacas desc. involuntario | B6: n | C6: VDI | D6: VA×((TDIv+TMv)/100) | E6: ='Parámetros base'!E14*(('Parámetros base'!E15+'Parámetros base'!E16)/100) -> 13.6
A7: Vacas desc. voluntario | B7: n | C7: VDV | D7: SI(NE>0,NE-NV,0), SI=Condicional | E7: =IF(E8>0,E8-E9,0) -> 4.809212
A8: Novillas excedentes | B8: n | C8: NE | D8: SI(HR>VDI,HR-VDI,0), SI=Condicional | E8: =IF(E5>E6,E5-E6,0) -> 9.6184239
A9: Novillas a venta | B9: n | C9: NV | D9: NE×TDVr/100 | E9: =E8*'Parámetros base'!E11/100 -> 4.809212
A10: Reemplazo anual | B10: % | C10: TR | D10: HR/VA×100 | E10: =E5/'Parámetros base'!E14*100 -> 34.144741
A11: Edad 1er servicio | B11: mes | C11: EIA | D11: (ln(ln(PIA/Ag)/-1)-Bg)/(-1×Cg), ln=logaritmo natural | E11: =(LN(LN('Parámetros base'!E8/'Parámetros base'!E5)/-1)-'Parámetros base'!E6)/(-1*'Parámetros base'!E7) -> 14.774626
A12: GDP nacim-1er serv. | B12: kg d | C12: GDP | D12: (PIA-Wt=0)/(EIA×30.4), Wt=0 peso estimado a nacimiento | E12: =('Parámetros base'!E8-32)/('Variables salida'!E11*30.4) -> 0.52989142
A13: Edad 1er parto | B13: mes | C13: EPA | D13: EIA+(IAC+DP)/30.4 | E13: =E11+('Parámetros base'!E9+'Parámetros base'!E18)/30.4 -> 24.741731
A14: Vida productiva | B14: mes | C14: VP | D14: 100/TR×12 | E14: =100/E10*12 -> 35.144504
A15: Leche esperada | B15: kg vaca | C15: PLn | D15: S (a×t^b×e^-c×t)/(DA+DP)×365, t=1 hasta DLAC | E15: =SUM('Curva '!F2:F306)/('Parámetros base'!E17+'Parámetros base'!E18)*365 -> 4663.5025
A16: Leche al pico | B16: kd d | C16: PP | D16: (a×(b/c)^b ×e^-c×(b/c)) | E16: =('Parámetros base'!E20*('Parámetros base'!E21/('Parámetros base'!E22/7))^'Parámetros base'!E21*EXP(-('Parámetros base'!E22/7)*('Parámetros base'!E21/('Parámetros base'!E22/7)))) -> 25.544459
A17: Días secos | B17: d | C17: DS | D17: (DP+DA)-DLAC | E17: =('Parámetros base'!E18+'Parámetros base'!E17)-'Parámetros base'!E23 -> 115
A18: Reducción por mastitis | B18: kg vaca | C18: RM | D18: ((S (a×t^b ×e^-c×t )×%R)/(DA+DP) ×365) × (IMC/100×VL))/VL | E18: =(SUM('Curva '!G2:G306)/('Parámetros base'!E17+'Parámetros base'!E18)*365)*('Parámetros base'!E27/100*'Variables salida'!E4)/'Variables salida'!E4 -> 66.388092
A19: Leche sin mastitis | B19: kg vaca | C19: PLsm | D19: PLn-RM | E19: =E15-E18 -> 4597.1144
A20: Grasa | B20: kg vaca | C20: PGR | D20: (S (a×t^b ×e^-c×t )×%GR)/(DA+DP) ×365)-(RM×%GR/100) | E20: =(SUM('Curva '!H2:H306)/('Parámetros base'!E17+'Parámetros base'!E18)*365)-('Variables salida'!E18*'Parámetros base'!E24/100) -> 198.60886
A21: Proteína | B21: kg vaca | C21: PPR | D21: (S (a×t^b ×e^-c×t )×%PR)/(DA+DP) ×365)-(RM×%PR/100) | E21: =(SUM('Curva '!I2:I306)/('Parámetros base'!E17+'Parámetros base'!E18)*365)-('Variables salida'!E18*'Parámetros base'!E25/100) -> 160.91929
A22: Lactosa + minerales | B22: kg vaca | C22: PLM | D22: ((PLn×%LM/100)/(DA+DP) ×365)-(RM×%LM/100) | E22: =((E15*'Parámetros base'!E26/100)/('Parámetros base'!E17+'Parámetros base'!E18)*365)-('Variables salida'!E18*'Parámetros base'!E26/100) -> 217.25976
A23: Sólidos totales | B23: kg hato | C23: PSOL | D23: (PGR+PPR+PLM)×VL | E23: =(E20+E21+E22)*E4 -> 31377.263
A24: Carne canal | B24: kg hato | C24: PCAR | D24: (Ag×%RC/100) × (NE-NV) | E24: =('Parámetros base'!E5*'Parámetros base'!E19/100)*('Variables salida'!E8-'Variables salida'!E9) -> 1125.1248
A25: Consumo concentrado | B25: kg hato | C25: CON | D25: ((S (a×t^b ×e^-c×t )×%AL×))/(DA+DP)×365)×VL | E25: =(SUM('Curva '!J2:J306)/('Parámetros base'!E17+'Parámetros base'!E18)*365)*'Variables salida'!E4 -> 98612.215
A26: Ingresos COP | B26: $ hato | C26: IT | D26: (PGR+PPR)×VL×$KGP + PLM×$LM×VL+(NE-NV)×PCAR×$CAR+NV×$NOV | E26: =(E20+E21)*E4*'Parámetros base'!E31+'Variables salida'!E22*'Parámetros base'!E32*'Variables salida'!E4+('Variables salida'!E8-'Variables salida'!E9)*'Variables salida'!E24*'Parámetros base'!E33+'Variables salida'!E9*'Parámetros base'!E34 -> 1.1306147e+09 | H26: =E26 -> 1.1306147e+09
A27: Costos COP | B27: $ hato | C27: CT | D27: [$CON×(CON+CON/3)]+(VL×$VAC)+(HR×$REM)+$AD | E27: =('Parámetros base'!E35*('Variables salida'!E25+'Variables salida'!E25/3))+('Variables salida'!E4*'Parámetros base'!E37)+('Variables salida'!E5*'Parámetros base'!E36)+'Parámetros base'!E38 -> 4.185588e+08 | H27: =E27 -> 4.185588e+08
A28: Margen bruto COP | B28: $ hato | C28: $MB | D28: IT-CT | E28: =E26-E27 -> 7.1205594e+08 | H28: =E28 -> 7.1205594e+08

Sheet Curva 
A1: CURVA DE LACTANCIA PROMEDIO DEL HATO | E1: Día | F1: Litros | G1: Reducción por mastitis (kg) | H1: Grasa (kg) | I1: Proteína (kg) | J1: Concentrado (kg)
A2: User-Defined Model: y=a*x^b*exp(-c*x) | E2: 1 | F2: =$B$4*E2^$B$5*EXP(-$B$6*E2) -> 18.758789 | G2: =F2*0% -> 0 | H2: =F2*$B$19/100 -> 0.81043486 | I2: =F2*$B$20/100 -> 0.65664037 | J2: =F2/$B$24 -> 9.3793945
A3: Coefficient Data: | E3: 2 | F3: =$B$4*E3^$B$5*EXP(-$B$6*E3) -> 20.456531 | G3: =F3*0% -> 0 | H3: =F3*$B$19/100 -> 0.88378231 | I3: =F3*$B$20/100 -> 0.71606884 | J3: =F3/$B$24 -> 10.228266
A4: a = | B4: 18.850127 | E4: 3 | F4: =$B$4*E4^$B$5*EXP(-$B$6*E4) -> 21.476672 | G4: =F4*0% -> 0 | H4: =F4*$B$19/100 -> 0.92785538 | I4: =F4*$B$20/100 -> 0.75177826 | J4: =F4/$B$24 -> 10.738336
A5: b = | B5: 0.13200236 | E5: 4 | F5: =$B$4*E5^$B$5*EXP(-$B$6*E5) -> 22.199833 | G5: =F5*0% -> 0 | H5: =F5*$B$19/100 -> 0.95909808 | I5: =F5*$B$20/100 -> 0.7770921 | J5: =F5/$B$24 -> 11.099917
A6: c = | B6: 0.0048572496 | E6: 5 | F6: =$B$4*E6^$B$5*EXP(-$B$6*E6) -> 22.752681 | G6: =F6*0% -> 0 | H6: =F6*$B$19/100 -> 0.98298275 | I6: =F6*$B$20/100 -> 0.79644422 | J6: =F6/$B$24 -> 11.376341
E7: 6 | F7: =$B$4*E7^$B$5*EXP(-$B$6*E7) -> 23.193977 | G7: =F7*0% -> 0 | H7: =F7*$B$19/100 -> 1.002048 | I7: =F7*$B$20/100 -> 0.81189151 | J7: =F7/$B$24 -> 11.596988
A8: DLAC | B8: 305 | E8: 7 | F8: =$B$4*E8^$B$5*EXP(-$B$6*E8) -> 23.556072 | G8: =F8*0% -> 0 | H8: =F8*$B$19/100 -> 1.0176916 | I8: =F8*$B$20/100 -> 0.82456645 | J8: =F8/$B$24 -> 11.778036
A9: Día al pico | B9: =B5/B6 -> 27.176359 | E9: 8 | F9: =$B$4*E9^$B$5*EXP(-$B$6*E9) -> 23.858793 | G9: =F9*0% -> 0 | H9: =F9*$B$19/100 -> 1.03077 | I9: =F9*$B$20/100 -> 0.83516302 | J9: =F9/$B$24 -> 11.929397
A10: Litros al pico | B10: =B4*((B5/B6)^B5)*EXP(-B5) -> 25.54483 | E10: 9 | F10: =$B$4*E10^$B$5*EXP(-$B$6*E10) -> 24.115221 | G10: =F10*0% -> 0 | H10: =F10*$B$19/100 -> 1.0418485 | I10: =F10*$B$20/100 -> 0.84413913 | J10: =F10/$B$24 -> 12.057611
A11: Prod. Total | B11: {=SUM(B4*(_xlfn.SEQUENCE(B8)^B5)*EXP(-B6*_xlfn.SEQUENCE(B8)))} -> 5366.2221 | E11: 10 | F11: =$B$4*E11^$B$5*EXP(-$B$6*E11) -> 24.334469 | G11: =F11*0% -> 0 | H11: =F11*$B$19/100 -> 1.0513206 | I11: =F11*$B$20/100 -> 0.85181376 | J11: =F11/$B$24 -> 12.167234
E12: 11 | F12: =$B$4*E12^$B$5*EXP(-$B$6*E12) -> 24.523154 | G12: =F12*0% -> 0 | H12: =F12*$B$19/100 -> 1.0594724 | I12: =F12*$B$20/100 -> 0.85841858 | J12: =F12/$B$24 -> 12.261577
A13: Reducción por mastitis | E13: 12 | F13: =$B$4*E13^$B$5*EXP(-$B$6*E13) -> 24.686245 | G13: =F13*0% -> 0 | H13: =F13*$B$19/100 -> 1.0665184 | I13: =F13*$B$20/100 -> 0.86412747 | J13: =F13/$B$24 -> 12.343122
A14: d0-d7 | B14: 1 | E14: 13 | F14: =$B$4*E14^$B$5*EXP(-$B$6*E14) -> 24.827571 | G14: =F14*0% -> 0 | H14: =F14*$B$19/100 -> 1.0726241 | I14: =F14*$B$20/100 -> 0.86907451 | J14: =F14/$B$24 -> 12.413785
A15: d8-d35 | B15: 0.24 | E15: 14 | F15: =$B$4*E15^$B$5*EXP(-$B$6*E15) -> 24.950153 | G15: =F15*0% -> 0 | H15: =F15*$B$19/100 -> 1.07792 | I15: =F15*$B$20/100 -> 0.87336542 | J15: =F15/$B$24 -> 12.475076
A16: d36-d70 | B16: 0.11 | E16: 15 | F16: =$B$4*E16^$B$5*EXP(-$B$6*E16) -> 25.056416 | G16: =F16*0% -> 0 | H16: =F16*$B$19/100 -> 1.0825109 | I16: =F16*$B$20/100 -> 0.8770851 | J16: =F16/$B$24 -> 12.528208
A17: d71-DLAC | B17: 0.08 | E17: 16 | F17: =$B$4*E17^$B$5*EXP(-$B$6*E17) -> 25.14834 | G17: =F17*0% -> 0 | H17: =F17*$B$19/100 -> 1.0864823 | I17: =F17*$B$20/100 -> 0.88030286 | J17: =F17/$B$24 -> 12.57417
E18: 17 | F18: =$B$4*E18^$B$5*EXP(-$B$6*E18) -> 25.227565 | G18: =F18*0% -> 0 | H18: =F18*$B$19/100 -> 1.089905 | I18: =F18*$B$20/100 -> 0.88307607 | J18: =F18/$B$24 -> 12.613782
A19: Grasa | B19: ='Parámetros base'!E24 -> 4.3202941 | E19: 18 | F19: =$B$4*E19^$B$5*EXP(-$B$6*E19) -> 25.295463 | G19: =F19*0% -> 0 | H19: =F19*$B$19/100 -> 1.0928384 | I19: =F19*$B$20/100 -> 0.88545279 | J19: =F19/$B$24 -> 12.647731
A20: Proteína | B20: ='Parámetros base'!E25 -> 3.5004412 | E20: 19 | F20: =$B$4*E20^$B$5*EXP(-$B$6*E20) -> 25.353196 | G20: =F20*0% -> 0 | H20: =F20*$B$19/100 -> 1.0953326 | I20: =F20*$B$20/100 -> 0.88747371 | J20: =F20/$B$24 -> 12.676598
E21: 20 | F21: =$B$4*E21^$B$5*EXP(-$B$6*E21) -> 25.401758 | G21: =F21*0% -> 0 | H21: =F21*$B$19/100 -> 1.0974307 | I21: =F21*$B$20/100 -> 0.88917359 | J21: =F21/$B$24 -> 12.700879
A22: Consumo de concentrado | E22: 21 | F22: =$B$4*E22^$B$5*EXP(-$B$6*E22) -> 25.442005 | G22: =F22*0% -> 0 | H22: =F22*$B$19/100 -> 1.0991694 | I22: =F22*$B$20/100 -> 0.89058242 | J22: =F22/$B$24 -> 12.721002
A23: Relación | B23: kg Leche | C23: kg Con | E23: 22 | F23: =$B$4*E23^$B$5*EXP(-$B$6*E23) -> 25.474681 | G23: =F23*0% -> 0 | H23: =F23*$B$19/100 -> 1.1005811 | I23: =F23*$B$20/100 -> 0.89172622 | J23: =F23/$B$24 -> 12.73734
A24: d0-d100 | B24: 2 | C24: 1 | E24: 23 | F24: =$B$4*E24^$B$5*EXP(-$B$6*E24) -> 25.500436 | G24: =F24*0% -> 0 | H24: =F24*$B$19/100 -> 1.1016938 | I24: =F24*$B$20/100 -> 0.89262775 | J24: =F24/$B$24 -> 12.750218
A25: d101-d200 | B25: 3 | C25: 1 | E25: 24 | F25: =$B$4*E25^$B$5*EXP(-$B$6*E25) -> 25.519842 | G25: =F25*0% -> 0 | H25: =F25*$B$19/100 -> 1.1025322 | I25: =F25*$B$20/100 -> 0.89330705 | J25: =F25/$B$24 -> 12.759921
A26: d201-DLAC | B26: 4 | C26: 1 | E26: 25 | F26: =$B$4*E26^$B$5*EXP(-$B$6*E26) -> 25.533405 | G26: =F26*0% -> 0 | H26: =F26*$B$19/100 -> 1.1031182 | I26: =F26*$B$20/100 -> 0.89378183 | J26: =F26/$B$24 -> 12.766703
E27: 26 | F27: =$B$4*E27^$B$5*EXP(-$B$6*E27) -> 25.541577 | G27: =F27*0% -> 0 | H27: =F27*$B$19/100 -> 1.1034712 | I27: =F27*$B$20/100 -> 0.89406787 | J27: =F27/$B$24 -> 12.770788
E28: 27 | F28: =$B$4*E28^$B$5*EXP(-$B$6*E28) -> 25.544758 | G28: =F28*0% -> 0 | H28: =F28*$B$19/100 -> 1.1036087 | I28: =F28*$B$20/100 -> 0.89417924 | J28: =F28/$B$24 -> 12.772379
E29: 28 | F29: =$B$4*E29^$B$5*EXP(-$B$6*E29) -> 25.543312 | G29: =F29*0% -> 0 | H29: =F29*$B$19/100 -> 1.1035462 | I29: =F29*$B$20/100 -> 0.8941286 | J29: =F29/$B$24 -> 12.771656
E30: 29 | F30: =$B$4*E30^$B$5*EXP(-$B$6*E30) -> 25.537562 | G30: =F30*0% -> 0 | H30: =F30*$B$19/100 -> 1.1032978 | I30: =F30*$B$20/100 -> 0.89392735 | J30: =F30/$B$24 -> 12.768781
E31: 30 | F31: =$B$4*E31^$B$5*EXP(-$B$6*E31) -> 25.527805 | G31: =F31*0% -> 0 | H31: =F31*$B$19/100 -> 1.1028762 | I31: =F31*$B$20/100 -> 0.89358578 | J31: =F31/$B$24 -> 12.763902
E32: 31 | F32: =$B$4*E32^$B$5*EXP(-$B$6*E32) -> 25.514306 | G32: =F32*0% -> 0 | H32: =F32*$B$19/100 -> 1.1022931 | I32: =F32*$B$20/100 -> 0.89311328 | J32: =F32/$B$24 -> 12.757153
E33: 32 | F33: =$B$4*E33^$B$5*EXP(-$B$6*E33) -> 25.49731 | G33: =F33*0% -> 0 | H33: =F33*$B$19/100 -> 1.1015588 | I33: =F33*$B$20/100 -> 0.89251835 | J33: =F33/$B$24 -> 12.748655
E34: 33 | F34: =$B$4*E34^$B$5*EXP(-$B$6*E34) -> 25.47704 | G34: =F34*0% -> 0 | H34: =F34*$B$19/100 -> 1.1006831 | I34: =F34*$B$20/100 -> 0.8918088 | J34: =F34/$B$24 -> 12.73852
E35: 34 | F35: =$B$4*E35^$B$5*EXP(-$B$6*E35) -> 25.453699 | G35: =F35*0% -> 0 | H35: =F35*$B$19/100 -> 1.0996746 | I35: =F35*$B$20/100 -> 0.89099175 | J35: =F35/$B$24 -> 12.726849
E36: 35 | F36: =$B$4*E36^$B$5*EXP(-$B$6*E36) -> 25.427474 | G36: =F36*0% -> 0 | H36: =F36*$B$19/100 -> 1.0985417 | I36: =F36*$B$20/100 -> 0.89007377 | J36: =F36/$B$24 -> 12.713737
E37: 36 | F37: =$B$4*E37^$B$5*EXP(-$B$6*E37) -> 25.398538 | G37: =F37*0% -> 0 | H37: =F37*$B$19/100 -> 1.0972915 | I37: =F37*$B$20/100 -> 0.88906088 | J37: =F37/$B$24 -> 12.699269
E38: 37 | F38: =$B$4*E38^$B$5*EXP(-$B$6*E38) -> 25.36705 | G38: =F38*0% -> 0 | H38: =F38*$B$19/100 -> 1.0959312 | I38: =F38*$B$20/100 -> 0.88795867 | J38: =F38/$B$24 -> 12.683525
... E97: 96 | F97: =$B$4*E97^$B$5*EXP(-$B$6*E97) -> 21.600758 | G97: =F97*0% -> 0 | H97: =F97*$B$19/100 -> 0.93321628 | I97: =F97*$B$20/100 -> 0.75612183 | J97: =F97/$B$24 -> 10.800379
E98: 97 | F98: =$B$4*E98^$B$5*EXP(-$B$6*E98) -> 21.525517 | G98: =F98*$B$14 -> 21.525517 | H98: =F98*$B$19/100 -> 0.92996565 | I98: =F98*$B$20/100 -> 0.75348807 | J98: =F98/$B$24 -> 10.762759
...

Sheet LISTAS
B2: Razas | C2: Categoría animal | D2: Estado reproductivo | E2: Lactancia (núm. Parto) | F2: Sí/No | G2: Tipo de servicio | H2: Distribución
B3: Holstein | C3: Ternera | D3: Vacía | E3: 1 | F3: Sí | G3: IA Convencional | H3: Normal
B4: Jersey | C4: Novilla de levante | D4: En servicio | E4: 2 | F4: No | G4: IA Sexada | H4: Discreta
B5: H+J- | C5: Novilla preñada | D5: Preñada confirmada | E5: 3 | G5: Monta natural | H5: Exponencial
B6: H-J+ | C6: Vaca lactante | D6: Preñada por confirmar | E6: 4 | G6: Transferencia de embriones | H6: Valor extremo
B7: F1 HxJ | C7: Desecho | D7: Repetidora | E7: 5 | H7: Constante
C8: Muerta | D8: Anestro | E8: 6
E9: 7+
